<?xml version="1.0"?>
<robot name="robot_final" xmlns:xacro="http://www.ros.org/wiki/xacro">
  
  <xacro:property name="PI" value="3.1415926535897931"/>

  <xacro:include filename="$(find robot_final)/urdf/robot_final.gazebo" />
  
  <xacro:robot_final />

  <static>false</static>
  
  <link name="base_link">
    <inertial>
      <mass value="2" />
      <origin xyz="0 0 0.0" />
      <inertia ixx="0.01" ixy="0.0" ixz="0.0"
        iyy="0.01" iyz="0.0" izz="0.5" />
    </inertial>
    <visual>
      <origin xyz="0 0 0" rpy="0 0 0"/>
      <geometry>
        <mesh filename="package://robot_final/meshes/base_link.STL" />
      </geometry>
    </visual>
    <collision>
      <origin xyz="0 0 0" py="0 0 0" />
      <geometry>
        <mesh filename="package://robot_final/meshes/base_link.STL" />
      </geometry>
    </collision>
  </link>
  
  <joint name="left_wheel_joint" type="continuous">
    <origin xyz="0 -0.1005 0.09" rpy="1.5708 0 0" />
    <parent link="base_link" />
    <child link="left_wheel_link" />
    <axis xyz="0 0 1" />
  </joint>
  <link name="left_wheel_link">
    <inertial>
      <origin xyz="0 0 0"/>
      <mass value="0.01" />
      <inertia ixx="0.001" ixy="0.0" ixz="0.0"
        iyy="0.001" iyz="0.0" izz="0.001" />
    </inertial>
    <visual>
      <origin xyz="0 0 0" rpy="0 0 0" />
      <geometry>
        <mesh filename="package://robot_final/meshes/left_wheel_link.STL" />
      </geometry>
    </visual>
    <collision>
      <origin xyz="0 0 0" rpy="0 0 0" />
      <geometry>
        <mesh filename="package://robot_final/meshes/left_wheel_link.STL" />
      </geometry>
    </collision>
  </link>
  
  
  <joint name="right_wheel_joint" type="continuous">
    <origin xyz="0 0.1005 0.09" rpy="1.5708 0 0" />
    <parent link="base_link" />
    <child link="right_wheel_link" />
    <axis xyz="0 0 1" />
  </joint>
  <link name="right_wheel_link">
    <inertial>
      <origin xyz="0 0 0"/>
      <mass value="0.01" />
      <inertia ixx="0.001" ixy="0.0" ixz="0.0"
        iyy="0.001" iyz="0.0" izz="0.001" />
    </inertial>
    <visual>
      <origin xyz="0 0 0" rpy="0 0 0" />
      <geometry>
        <mesh filename="package://robot_final/meshes/right_wheel_link.STL" />
      </geometry>
    </visual>
    <collision>
      <origin xyz="0 0 0" rpy="0 0 0" />
      <geometry>
        <mesh filename="package://robot_final/meshes/right_wheel_link.STL" />
      </geometry>
    </collision>
  </link>
  
  
  <joint name="caster1_joint" type="fixed">
    <origin xyz="0.12 0 0" rpy="1.5708 0 0" />
    <parent link="base_link" />
    <child link="caster1_link" />
    <axis xyz="0 0 1" />
  </joint>
  <link name="caster1_link">
    <inertial>
      <origin xyz="0 0 0" />
      <mass value="0.01" />
      <inertia ixx="0.001" ixy="0.0" ixz="0.0"
        iyy="0.001" iyz="0.0" izz="0.001" />
    </inertial>
    <visual>
      <origin xyz="0 0 0" rpy="0 0 0" />
      <geometry>
        <mesh filename="package://robot_final/meshes/caster1_link.STL" />
      </geometry>
    </visual>
    <collision>
      <origin xyz="0 0 0" rpy="0 0 0" />
      <geometry>
        <mesh filename="package://robot_final/meshes/caster1_link.STL" />
      </geometry>
    </collision>
  </link>
  
  
  <joint name="caster2_joint" type="fixed">
    <origin xyz="-0.12 0 0" rpy="1.6031 0.1812 0.0029334" />
    <parent link="base_link" />
    <child link="caster2_link" />
    <axis xyz="0.0028853 -0.031751 -0.99949" />
  </joint>
  <link name="caster2_link">
    <inertial>
      <origin xyz="0 0 0" />
      <mass value="0.01" />
      <inertia ixx="0.001" ixy="0.0" ixz="0.0"
        iyy="0.001" iyz="0.0" izz="0.001" />
    </inertial>
    <visual>
      <origin xyz="0 0 0" rpy="0 0 0" />
      <geometry>
        <mesh filename="package://robot_final/meshes/caster2_link.STL" />
      </geometry>
    </visual>
    <collision>
      <origin xyz="0 0 0" rpy="0 0 0" />
      <geometry>
        <mesh filename="package://robot_final/meshes/caster2_link.STL" />
      </geometry>
    </collision>
  </link>
  
  
  <joint name="camera_joint" type="fixed">
    <axis xyz="0 1 0" />
    <origin
        xyz="0.16 0 0.20"
        rpy="2.0 0 1.57" />
    <parent
      link="base_link" />
    <child
      link="camera_link" />
  </joint>
  <link name="camera_link">
    <visual>
      <origin
        xyz="0 0 0"
        rpy="0 0 0" />
      <geometry>
        <mesh
          filename="package://robot_final/meshes/asus_xtion_pro_live_camera.dae" scale="0.001 0.001 0.001"/>
      </geometry>
    </visual>
    <collision>
      <origin
        xyz="0 0 0"
        rpy="0 0 0" />
      <geometry>
        <mesh
          filename="package://robot_final/meshes/asus_xtion_pro_live_camera.dae" scale="0.001 0.001 0.001" />
      </geometry>
    </collision>
  </link>


 
  <joint name="camera_point_joint" type="fixed">
    <axis xyz="0 1 0" />
    <origin xyz="0.023 0 0.015" rpy="0 -1.571 -1.571" />
    <parent link="camera_link" />
    <child link="camera_point_link" />
  </joint>
  <link name="camera_point_link">
  </link>

  
  <joint name="hokuyo_joint" type="fixed">
    <axis xyz="0 1 0" />
    <origin xyz="0 0 0.25" rpy="0 0 0"/>
    <parent link="base_link"/>
    <child link="hokuyo_link"/>
	 <dynamics damping="0.7"/>
  </joint>
  <link name="hokuyo_link">
    <collision>
      <origin xyz="0 0 0" rpy="0 0 0"/>
      <geometry>
    <box size="0.1 0.1 0.1"/>
      </geometry>
    </collision>
    <visual>
      <origin xyz="0 0 0" rpy="0 0 0"/>
      <geometry>
        <mesh filename="package://simple_robot_LIDAR/meshes/hokuyo.dae"/>
      </geometry>
    </visual>
    <inertial>
      <mass value="1e-5" />
      <origin xyz="0 0 0" rpy="0 0 0"/>
      <inertia ixx="1e-6" ixy="0" ixz="0" iyy="1e-6" iyz="0" izz="1e-6" />
    </inertial>
  </link>
 
  

  <transmission name="left_wheel_transmission">
        <type>transmission_interface/SimpleTransmission</type>
        <joint name="left_wheel_joint">
            <hardwareInterface>hardware_interface/VelocityJointInterface</hardwareInterface>
        </joint>
        <actuator name="left_wheel_actuator">
            <mechanicalReduction>1</mechanicalReduction>
            <hardwareInterface>VelocityJointInterface</hardwareInterface>
        </actuator>
    </transmission>

    <transmission name="right_wheel_transmission">
        <type>transmission_interface/SimpleTransmission</type>
        <joint name="right_wheel_joint">
            <hardwareInterface>hardware_interface/VelocityJointInterface</hardwareInterface>
        </joint>
        <actuator name="right_wheel_actuator">
            <mechanicalReduction>1</mechanicalReduction>
            <hardwareInterface>VelocityJointInterface</hardwareInterface>
        </actuator>
    </transmission>
</robot>
